{
 "cells": [
  {
   "cell_type": "code",
   "execution_count": 1,
   "id": "05c41fdd",
   "metadata": {},
   "outputs": [],
   "source": [
    "import tensorflow as tf"
   ]
  },
  {
   "cell_type": "code",
   "execution_count": 2,
   "id": "13f4508d",
   "metadata": {},
   "outputs": [],
   "source": [
    "from keras.preprocessing.image import ImageDataGenerator"
   ]
  },
  {
   "cell_type": "code",
   "execution_count": 3,
   "id": "ad5db303",
   "metadata": {},
   "outputs": [],
   "source": [
    "train_datagen = ImageDataGenerator(rescale = 1./255,shear_range =  0.2,zoom_range = 0.2,horizontal_flip = True)"
   ]
  },
  {
   "cell_type": "code",
   "execution_count": 4,
   "id": "9a393ea8",
   "metadata": {},
   "outputs": [],
   "source": [
    "test_datagen = ImageDataGenerator(rescale = 1)"
   ]
  },
  {
   "cell_type": "code",
   "execution_count": 5,
   "id": "8abfe287",
   "metadata": {},
   "outputs": [
    {
     "name": "stdout",
     "output_type": "stream",
     "text": [
      "Found 5384 images belonging to 6 classes.\n",
      "Found 1686 images belonging to 6 classes.\n"
     ]
    }
   ],
   "source": [
    "x_train = train_datagen.flow_from_directory('fruit-dataset/train',target_size = (128,128),batch_size = 32,class_mode='categorical')\n",
    "\n",
    "x_test = test_datagen.flow_from_directory('fruit-dataset/test',target_size = (128,128),batch_size = 32,class_mode='categorical')"
   ]
  },
  {
   "cell_type": "code",
   "execution_count": 6,
   "id": "7e585d84",
   "metadata": {},
   "outputs": [],
   "source": [
    "from tensorflow.keras.models import Sequential\n",
    "from tensorflow.keras.layers import Dense\n",
    "from tensorflow.keras.layers import Convolution2D\n",
    "from tensorflow.keras.layers import MaxPooling2D\n",
    "from tensorflow.keras.layers import Flatten"
   ]
  },
  {
   "cell_type": "code",
   "execution_count": 7,
   "id": "372d124e",
   "metadata": {},
   "outputs": [],
   "source": [
    "model=Sequential()"
   ]
  },
  {
   "cell_type": "code",
   "execution_count": 8,
   "id": "ec25919c",
   "metadata": {},
   "outputs": [],
   "source": [
    "model.add(Convolution2D(32,(3,3),input_shape=(128,128,3),activation='relu'))"
   ]
  },
  {
   "cell_type": "code",
   "execution_count": 9,
   "id": "531d54bd",
   "metadata": {},
   "outputs": [],
   "source": [
    "model.add(MaxPooling2D(pool_size=(2,2)))"
   ]
  },
  {
   "cell_type": "code",
   "execution_count": 10,
   "id": "8be76115",
   "metadata": {},
   "outputs": [],
   "source": [
    "model.add(Flatten())"
   ]
  },
  {
   "cell_type": "code",
   "execution_count": 11,
   "id": "86df1c52",
   "metadata": {},
   "outputs": [],
   "source": [
    "model.add(Dense(40, activation='relu', kernel_initializer='uniform'))"
   ]
  },
  {
   "cell_type": "code",
   "execution_count": 12,
   "id": "6751a479",
   "metadata": {},
   "outputs": [],
   "source": [
    "model.add(Dense(20, activation='relu', kernel_initializer='random_uniform'))"
   ]
  },
  {
   "cell_type": "code",
   "execution_count": 13,
   "id": "a2fc18f6",
   "metadata": {},
   "outputs": [],
   "source": [
    "model.add(Dense(6, activation='softmax', kernel_initializer='random_uniform'))"
   ]
  },
  {
   "cell_type": "code",
   "execution_count": 14,
   "id": "d37cae73",
   "metadata": {},
   "outputs": [],
   "source": [
    "model.compile(loss='cateforical_crossentropy',optimizer=\"adam\",metrics = [\"accuracy\"])"
   ]
  },
  {
   "cell_type": "code",
   "execution_count": 15,
   "id": "ecf3691d",
   "metadata": {},
   "outputs": [
    {
     "name": "stderr",
     "output_type": "stream",
     "text": [
      "C:\\Users\\karun\\AppData\\Local\\Temp/ipykernel_21896/1813700871.py:1: UserWarning: `Model.fit_generator` is deprecated and will be removed in a future version. Please use `Model.fit`, which supports generators.\n",
      "  model.fit_generator(x_train,steps_per_epoch=len(x_train)/32,epochs =3,validation_data=x_test,validation_steps=len(x_test)/32)\n"
     ]
    },
    {
     "name": "stdout",
     "output_type": "stream",
     "text": [
      "Epoch 1/3\n"
     ]
    },
    {
     "ename": "ValueError",
     "evalue": "in user code:\n\n    File \"C:\\Users\\karun\\anaconda3\\lib\\site-packages\\keras\\engine\\training.py\", line 1021, in train_function  *\n        return step_function(self, iterator)\n    File \"C:\\Users\\karun\\anaconda3\\lib\\site-packages\\keras\\engine\\training.py\", line 1010, in step_function  **\n        outputs = model.distribute_strategy.run(run_step, args=(data,))\n    File \"C:\\Users\\karun\\anaconda3\\lib\\site-packages\\keras\\engine\\training.py\", line 1000, in run_step  **\n        outputs = model.train_step(data)\n    File \"C:\\Users\\karun\\anaconda3\\lib\\site-packages\\keras\\engine\\training.py\", line 860, in train_step\n        loss = self.compute_loss(x, y, y_pred, sample_weight)\n    File \"C:\\Users\\karun\\anaconda3\\lib\\site-packages\\keras\\engine\\training.py\", line 918, in compute_loss\n        return self.compiled_loss(\n    File \"C:\\Users\\karun\\anaconda3\\lib\\site-packages\\keras\\engine\\compile_utils.py\", line 184, in __call__\n        self.build(y_pred)\n    File \"C:\\Users\\karun\\anaconda3\\lib\\site-packages\\keras\\engine\\compile_utils.py\", line 133, in build\n        self._losses = tf.nest.map_structure(self._get_loss_object, self._losses)\n    File \"C:\\Users\\karun\\anaconda3\\lib\\site-packages\\keras\\engine\\compile_utils.py\", line 272, in _get_loss_object\n        loss = losses_mod.get(loss)\n    File \"C:\\Users\\karun\\anaconda3\\lib\\site-packages\\keras\\losses.py\", line 2369, in get\n        return deserialize(identifier)\n    File \"C:\\Users\\karun\\anaconda3\\lib\\site-packages\\keras\\losses.py\", line 2324, in deserialize\n        return deserialize_keras_object(\n    File \"C:\\Users\\karun\\anaconda3\\lib\\site-packages\\keras\\utils\\generic_utils.py\", line 709, in deserialize_keras_object\n        raise ValueError(\n\n    ValueError: Unknown loss function: cateforical_crossentropy. Please ensure this object is passed to the `custom_objects` argument. See https://www.tensorflow.org/guide/keras/save_and_serialize#registering_the_custom_object for details.\n",
     "output_type": "error",
     "traceback": [
      "\u001b[1;31m---------------------------------------------------------------------------\u001b[0m",
      "\u001b[1;31mValueError\u001b[0m                                Traceback (most recent call last)",
      "\u001b[1;32m~\\AppData\\Local\\Temp/ipykernel_21896/1813700871.py\u001b[0m in \u001b[0;36m<module>\u001b[1;34m\u001b[0m\n\u001b[1;32m----> 1\u001b[1;33m \u001b[0mmodel\u001b[0m\u001b[1;33m.\u001b[0m\u001b[0mfit_generator\u001b[0m\u001b[1;33m(\u001b[0m\u001b[0mx_train\u001b[0m\u001b[1;33m,\u001b[0m\u001b[0msteps_per_epoch\u001b[0m\u001b[1;33m=\u001b[0m\u001b[0mlen\u001b[0m\u001b[1;33m(\u001b[0m\u001b[0mx_train\u001b[0m\u001b[1;33m)\u001b[0m\u001b[1;33m/\u001b[0m\u001b[1;36m32\u001b[0m\u001b[1;33m,\u001b[0m\u001b[0mepochs\u001b[0m \u001b[1;33m=\u001b[0m\u001b[1;36m3\u001b[0m\u001b[1;33m,\u001b[0m\u001b[0mvalidation_data\u001b[0m\u001b[1;33m=\u001b[0m\u001b[0mx_test\u001b[0m\u001b[1;33m,\u001b[0m\u001b[0mvalidation_steps\u001b[0m\u001b[1;33m=\u001b[0m\u001b[0mlen\u001b[0m\u001b[1;33m(\u001b[0m\u001b[0mx_test\u001b[0m\u001b[1;33m)\u001b[0m\u001b[1;33m/\u001b[0m\u001b[1;36m32\u001b[0m\u001b[1;33m)\u001b[0m\u001b[1;33m\u001b[0m\u001b[1;33m\u001b[0m\u001b[0m\n\u001b[0m",
      "\u001b[1;32m~\\anaconda3\\lib\\site-packages\\keras\\engine\\training.py\u001b[0m in \u001b[0;36mfit_generator\u001b[1;34m(self, generator, steps_per_epoch, epochs, verbose, callbacks, validation_data, validation_steps, validation_freq, class_weight, max_queue_size, workers, use_multiprocessing, shuffle, initial_epoch)\u001b[0m\n\u001b[0;32m   2207\u001b[0m         \u001b[1;34m'Please use `Model.fit`, which supports generators.'\u001b[0m\u001b[1;33m,\u001b[0m\u001b[1;33m\u001b[0m\u001b[1;33m\u001b[0m\u001b[0m\n\u001b[0;32m   2208\u001b[0m         stacklevel=2)\n\u001b[1;32m-> 2209\u001b[1;33m     return self.fit(\n\u001b[0m\u001b[0;32m   2210\u001b[0m         \u001b[0mgenerator\u001b[0m\u001b[1;33m,\u001b[0m\u001b[1;33m\u001b[0m\u001b[1;33m\u001b[0m\u001b[0m\n\u001b[0;32m   2211\u001b[0m         \u001b[0msteps_per_epoch\u001b[0m\u001b[1;33m=\u001b[0m\u001b[0msteps_per_epoch\u001b[0m\u001b[1;33m,\u001b[0m\u001b[1;33m\u001b[0m\u001b[1;33m\u001b[0m\u001b[0m\n",
      "\u001b[1;32m~\\anaconda3\\lib\\site-packages\\keras\\utils\\traceback_utils.py\u001b[0m in \u001b[0;36merror_handler\u001b[1;34m(*args, **kwargs)\u001b[0m\n\u001b[0;32m     65\u001b[0m     \u001b[1;32mexcept\u001b[0m \u001b[0mException\u001b[0m \u001b[1;32mas\u001b[0m \u001b[0me\u001b[0m\u001b[1;33m:\u001b[0m  \u001b[1;31m# pylint: disable=broad-except\u001b[0m\u001b[1;33m\u001b[0m\u001b[1;33m\u001b[0m\u001b[0m\n\u001b[0;32m     66\u001b[0m       \u001b[0mfiltered_tb\u001b[0m \u001b[1;33m=\u001b[0m \u001b[0m_process_traceback_frames\u001b[0m\u001b[1;33m(\u001b[0m\u001b[0me\u001b[0m\u001b[1;33m.\u001b[0m\u001b[0m__traceback__\u001b[0m\u001b[1;33m)\u001b[0m\u001b[1;33m\u001b[0m\u001b[1;33m\u001b[0m\u001b[0m\n\u001b[1;32m---> 67\u001b[1;33m       \u001b[1;32mraise\u001b[0m \u001b[0me\u001b[0m\u001b[1;33m.\u001b[0m\u001b[0mwith_traceback\u001b[0m\u001b[1;33m(\u001b[0m\u001b[0mfiltered_tb\u001b[0m\u001b[1;33m)\u001b[0m \u001b[1;32mfrom\u001b[0m \u001b[1;32mNone\u001b[0m\u001b[1;33m\u001b[0m\u001b[1;33m\u001b[0m\u001b[0m\n\u001b[0m\u001b[0;32m     68\u001b[0m     \u001b[1;32mfinally\u001b[0m\u001b[1;33m:\u001b[0m\u001b[1;33m\u001b[0m\u001b[1;33m\u001b[0m\u001b[0m\n\u001b[0;32m     69\u001b[0m       \u001b[1;32mdel\u001b[0m \u001b[0mfiltered_tb\u001b[0m\u001b[1;33m\u001b[0m\u001b[1;33m\u001b[0m\u001b[0m\n",
      "\u001b[1;32m~\\anaconda3\\lib\\site-packages\\tensorflow\\python\\framework\\func_graph.py\u001b[0m in \u001b[0;36mautograph_handler\u001b[1;34m(*args, **kwargs)\u001b[0m\n\u001b[0;32m   1145\u001b[0m           \u001b[1;32mexcept\u001b[0m \u001b[0mException\u001b[0m \u001b[1;32mas\u001b[0m \u001b[0me\u001b[0m\u001b[1;33m:\u001b[0m  \u001b[1;31m# pylint:disable=broad-except\u001b[0m\u001b[1;33m\u001b[0m\u001b[1;33m\u001b[0m\u001b[0m\n\u001b[0;32m   1146\u001b[0m             \u001b[1;32mif\u001b[0m \u001b[0mhasattr\u001b[0m\u001b[1;33m(\u001b[0m\u001b[0me\u001b[0m\u001b[1;33m,\u001b[0m \u001b[1;34m\"ag_error_metadata\"\u001b[0m\u001b[1;33m)\u001b[0m\u001b[1;33m:\u001b[0m\u001b[1;33m\u001b[0m\u001b[1;33m\u001b[0m\u001b[0m\n\u001b[1;32m-> 1147\u001b[1;33m               \u001b[1;32mraise\u001b[0m \u001b[0me\u001b[0m\u001b[1;33m.\u001b[0m\u001b[0mag_error_metadata\u001b[0m\u001b[1;33m.\u001b[0m\u001b[0mto_exception\u001b[0m\u001b[1;33m(\u001b[0m\u001b[0me\u001b[0m\u001b[1;33m)\u001b[0m\u001b[1;33m\u001b[0m\u001b[1;33m\u001b[0m\u001b[0m\n\u001b[0m\u001b[0;32m   1148\u001b[0m             \u001b[1;32melse\u001b[0m\u001b[1;33m:\u001b[0m\u001b[1;33m\u001b[0m\u001b[1;33m\u001b[0m\u001b[0m\n\u001b[0;32m   1149\u001b[0m               \u001b[1;32mraise\u001b[0m\u001b[1;33m\u001b[0m\u001b[1;33m\u001b[0m\u001b[0m\n",
      "\u001b[1;31mValueError\u001b[0m: in user code:\n\n    File \"C:\\Users\\karun\\anaconda3\\lib\\site-packages\\keras\\engine\\training.py\", line 1021, in train_function  *\n        return step_function(self, iterator)\n    File \"C:\\Users\\karun\\anaconda3\\lib\\site-packages\\keras\\engine\\training.py\", line 1010, in step_function  **\n        outputs = model.distribute_strategy.run(run_step, args=(data,))\n    File \"C:\\Users\\karun\\anaconda3\\lib\\site-packages\\keras\\engine\\training.py\", line 1000, in run_step  **\n        outputs = model.train_step(data)\n    File \"C:\\Users\\karun\\anaconda3\\lib\\site-packages\\keras\\engine\\training.py\", line 860, in train_step\n        loss = self.compute_loss(x, y, y_pred, sample_weight)\n    File \"C:\\Users\\karun\\anaconda3\\lib\\site-packages\\keras\\engine\\training.py\", line 918, in compute_loss\n        return self.compiled_loss(\n    File \"C:\\Users\\karun\\anaconda3\\lib\\site-packages\\keras\\engine\\compile_utils.py\", line 184, in __call__\n        self.build(y_pred)\n    File \"C:\\Users\\karun\\anaconda3\\lib\\site-packages\\keras\\engine\\compile_utils.py\", line 133, in build\n        self._losses = tf.nest.map_structure(self._get_loss_object, self._losses)\n    File \"C:\\Users\\karun\\anaconda3\\lib\\site-packages\\keras\\engine\\compile_utils.py\", line 272, in _get_loss_object\n        loss = losses_mod.get(loss)\n    File \"C:\\Users\\karun\\anaconda3\\lib\\site-packages\\keras\\losses.py\", line 2369, in get\n        return deserialize(identifier)\n    File \"C:\\Users\\karun\\anaconda3\\lib\\site-packages\\keras\\losses.py\", line 2324, in deserialize\n        return deserialize_keras_object(\n    File \"C:\\Users\\karun\\anaconda3\\lib\\site-packages\\keras\\utils\\generic_utils.py\", line 709, in deserialize_keras_object\n        raise ValueError(\n\n    ValueError: Unknown loss function: cateforical_crossentropy. Please ensure this object is passed to the `custom_objects` argument. See https://www.tensorflow.org/guide/keras/save_and_serialize#registering_the_custom_object for details.\n"
     ]
    }
   ],
   "source": [
    "model.fit_generator(x_train,steps_per_epoch=len(x_train)/32,epochs =3,validation_data=x_test,validation_steps=len(x_test)/32)"
   ]
  },
  {
   "cell_type": "code",
   "execution_count": null,
   "id": "4a15c450",
   "metadata": {},
   "outputs": [],
   "source": []
  }
 ],
 "metadata": {
  "kernelspec": {
   "display_name": "Python 3 (ipykernel)",
   "language": "python",
   "name": "python3"
  },
  "language_info": {
   "codemirror_mode": {
    "name": "ipython",
    "version": 3
   },
   "file_extension": ".py",
   "mimetype": "text/x-python",
   "name": "python",
   "nbconvert_exporter": "python",
   "pygments_lexer": "ipython3",
   "version": "3.9.7"
  }
 },
 "nbformat": 4,
 "nbformat_minor": 5
}
